Workbook

Sheet CV
A1: Α/Α | B1: ΕΡΓΑ | C1: ΧΡΟΝΙΚΟ ΔΙΑΣΤΗΜΑ | D1: ΑΝΘΡΩΠΟΜΗΝΕΣ
A2: 1 | B2: Εγκατάσταση, παραμετροποίηση και παροχή υπηρεσιών υποστήριξης Blade IBM Server, με IBM Storage για την πλήρη εικονοποίηση όλων των φυσικών servers του λιμενικού σώματος σε virtual περιβάλλον | C2: 01/06/2013 -31/12/2013 | D2: 6
A3: 2 | B3: Εγκατάσταση παραμετροποίηση και παροχή υπηρεσιών υποστήριξης όλων των υπηρεσιών της Hellas Gold | C3: 30/04/2013 -30/05/2013 | D3: 1
A4: 3 | B4: Εγκατάσταση – παραμετροποίηση και παροχή υπηρεσιών υποστήριξης backup SW και παραμετροποίηση – βελτιστοποίηση mail server υπουργείου | C4: 01/02/2014 -01/03/2014 | D4: 2
A5: 4 | B5: Εγκατάσταση παραμετροποίηση και παροχή υπηρεσιών υποστήριξης περιβάλλοντος Εισαγγελίας Αθηνών Storage Dell | C5: 10/03/2014 -10/05/2014 | D5: 2
A6: 5 | B6: Εγκατάσταση παραμετροποίηση και παροχή υπηρεσιών υποστήριξης virtualization Υπουργείου Δικαιοσύνης Storage Qnap | C6: 10/05/2014 -10/06/2014 | D6: 1
A7: 6 | B7: Εγκατάσταση – παραμετροποίηση και παροχή υπηρεσιών υποστήριξης εικονικού περιβάλλοντος λειτουργίας των εφαρμογών του Παρατηρητηρίου. Storage Dell | C7: 01/10/2014 -01/12/2014 | D7: 2
A8: 7 | B8: Εγκατάσταση και παραμετροποίηση και παροχή υπηρεσιών υποστήριξης των λειτουργικών συστημάτων, εγκατάσταση και παραμετροποίηση των servers του συστήματος. Υποστήριξη 2ου επιπέδου | C8: 01/01/2011 - 01/04/2011 | D8: 3
A9: 8 | B9: Εγκατάσταση και παραμετροποίηση και παροχή υπηρεσιών υποστήριξης ΙΤ εξοπλισμού, σε επίπεδο servers και τοπικών υπηρεσιών ανά τις πρεσβείες Storage HP | C9: 01/04/2011 - 01/07/2011 | D9: 3
A10: 9 | B10: Ανάπτυξη και εγκατάσταση λογισμικών και εξοπλισμού τους. Υποστήριξη συνολικού δικτύου ( servers, clients, software). Storage IBM | C10: 01/07/2010 - 01/09/2011 | D10: 9
A11: 10 | B11: Εγκατάσταση/παραμετροποίηση των ραντάρ, εγκατάσταση παραμετροποίηση των λογισμικών, υποστήριξη και επίλυση δυσλειτουργιών σε επίπεδο ραντάρ και λογισμικό αυτών σε επίπεδο 1ο , 2ο και 3ο . | C11: 07/07/2011 - 21/04/2012 | D11: 5
A12: 11 | B12: Εγκατάσταση/παραμετροποίηση των ραντάρ, εγκατάσταση παραμετροποίηση των λογισμικών, υποστήριξη και επίλυση δυσλειτουργιών σε επίπεδο ραντάρ και λογισμικό αυτών σε επίπεδο 1ο , 2ο και 3ο . | C12: 01/03/2009 - 01/11/2010 | D12: 10
A13: 12 | B13: Εγκατάσταση παραμετροποίηση και παροχή υπηρεσιών υποστήριξης Storage Dell | C13: 01/2014 – 12/2014 | D13: 5
... A39: 38 | B39: Συγγραφή Μελέτης Εφαρμογής | C39: 06/2024 – 07/2024 | D39: 1

Sheet ΑΝΑΛΥΣΗ
C2: ΑΝΘΡΩΠΟΜΗΝΕΣ ΕΜΠΕΙΡΙΑΣ | D2: 37 | F2: 2009 | R2: 2010 | AD2: 2011 | AP2: 2012 | BB2: 2013 | BN2: 2014 | BZ2: 2015 | CL2: 2016 | CX2: 2017 | DJ2: 2018 | DV2: 2019 | EH2: 2020 | ET2: 2021 | FF2: 2022 | FR2: 2023 | GD2: 2024 | GP2: 2025 | HB2: 2026
F3: 1 | G3: 2 | H3: 3 | I3: 4 | J3: 5 | K3: 6 | L3: 7 | M3: 8 | N3: 9 | O3: 10 | P3: 11 | Q3: 12 | R3: 1 | S3: 2 | T3: 3 | U3: 4 | V3: 5 | W3: 6 | X3: 7 | Y3: 8 | Z3: 9 | AA3: 10 | AB3: 11 | AC3: 12 | AD3: 1 | AE3: 2 | AF3: 3 | AG3: 4 | AH3: 5 | AI3: 6 | AJ3: 7 | AK3: 8 | AL3: 9 | AM3: 10 | AN3: 11 | AO3: 12 | AP3: 1 | AQ3: 2 | AR3: 3 | AS3: 4 | AT3: 5 | AU3: 6 | AV3: 7 | AW3: 8 | AX3: 9 | AY3: 10 | AZ3: 11 | BA3: 12 | BB3: 1 | BC3: 2 | BD3: 3 | BE3: 4 | BF3: 5 | BG3: 6 | BH3: 7 | BI3: 8 | BJ3: 9 | BK3: 10 | BL3: 11 | BM3: 12 | BN3: 1 | BO3: 2 | BP3: 3 | BQ3: 4 | BR3: 5 | BS3: 6 | BT3: 7 | BU3: 8 | BV3: 9 | BW3: 10 | BX3: 11 | BY3: 12 | BZ3: 1 | CA3: 2 | CB3: 3 | CC3: 4 | CD3: 5 | CE3: 6 | CF3: 7 | CG3: 8 | CH3: 9 | CI3: 10 | CJ3: 11 | CK3: 12 | CL3: 1 | CM3: 2 | CN3: 3 | CO3: 4 | CP3: 5 | CQ3: 6 | CR3: 7 | CS3: 8 | CT3: 9 | CU3: 10 | CV3: 11 | CW3: 12 | CX3: 1 | CY3: 2 | CZ3: 3 | DA3: 4 | DB3: 5 | DC3: 6 | DD3: 7 | DE3: 8 | DF3: 9 | DG3: 10 | DH3: 11 | DI3: 12 | DJ3: 1 | DK3: 2 | DL3: 3 | DM3: 4 | DN3: 5 | DO3: 6 | DP3: 7 | DQ3: 8 | DR3: 9 | DS3: 10 | DT3: 11 | DU3: 12 | DV3: 1 | DW3: 2 | DX3: 3 | DY3: 4 | DZ3: 5 | EA3: 6 | EB3: 7 | EC3: 8 | ED3: 9 | EE3: 10 | EF3: 11 | EG3: 12 | EH3: 1 | EI3: 2 | EJ3: 3 | EK3: 4 | EL3: 5 | EM3: 6 | EN3: 7 | EO3: 8 | EP3: 9 | EQ3: 10 | ER3: 11 | ES3: 12 | ET3: 1 | EU3: 2 | EV3: 3 | EW3: 4 | EX3: 5 | EY3: 6 | EZ3: 7 | FA3: 8 | FB3: 9 | FC3: 10 | FD3: 11 | FE3: 12 | FF3: 1 | FG3: 2 | FH3: 3 | FI3: 4 | FJ3: 5 | FK3: 6 | FL3: 7 | FM3: 8 | FN3: 9 | FO3: 10 | FP3: 11 | FQ3: 12 | FR3: 1 | FS3: 2 | FT3: 3 | FU3: 4 | FV3: 5 | FW3: 6 | FX3: 7 | FY3: 8 | FZ3: 9 | GA3: 10 | GB3: 11 | GC3: 12 | GD3: 1 | GE3: 2 | GF3: 3 | GG3: 4 | GH3: 5 | GI3: 6 | GJ3: 7 | GK3: 8 | GL3: 9 | GM3: 10 | GN3: 11 | GO3: 12 | GP3: 1 | GQ3: 2 | GR3: 3 | GS3: 4 | GT3: 5 | GU3: 6 | GV3: 7 | GW3: 8 | GX3: 9 | GY3: 10 | GZ3: 11 | HA3: 12 | HB3: 1 | HC3: 2 | HD3: 3 | HE3: 4 | HF3: 5 | HG3: 6 | HH3: 7 | HI3: 8 | HJ3: 9 | HK3: 10 | HL3: 11 | HM3: 12
A5: Α/Α | B5: ΕΡΓΑ | C5: ΕΤΗΣΙΑ ΣΥΝΟΛΑ | D5: ΑΜ | E5: X | F5: 10 | R5: 6 | AD5: 11 | AP5: 3 | BB5: 7 | BN5: 11 | BZ5: 5 | CL5: 2 | CX5: 11 | DJ5: 10 | DV5: 8 | EH5: 10 | ET5: 7 | FF5: 9 | FR5: 2 | GD5: 5 | GP5: 0 | HB5: 0
A6: =MATCH(C6,CV!$C$2:$C$39,0) -> 5 | B6: =VLOOKUP(A6,CV!$A$2:$B$1899,2,FALSE) -> Εγκατάσταση παραμετροποίηση και παροχή υπηρεσιών υποστήριξης virtualization Υπουργείου Δικαιοσύνης Storage Qnap | C6: 10/05/2014 -10/06/2014 | D6: 1 | E6: =COUNTIF(F6:ATU6,E5) -> 1 | BS6: X
A7: =MATCH(C7,CV!$C$2:$C$39,0) -> 30 | B7: =VLOOKUP(A7,CV!$A$2:$B$1899,2,FALSE) -> Αναβάθμιση/Μετάπτωση κεντρικής υποδομής ΕΜΥ - Storage | C7: 01/12/2021 – 01/01/2022 | D7: 1 | E7: =COUNTIF(F7:ATU7,$E$5) -> 1 | FF7: X
A8: =MATCH(C8,CV!$C$2:$C$39,0) -> 4 | B8: =VLOOKUP(A8,CV!$A$2:$B$1899,2,FALSE) -> Εγκατάσταση παραμετροποίηση και παροχή υπηρεσιών υποστήριξης περιβάλλοντος Εισαγγελίας Αθηνών Storage Dell | C8: 10/03/2014 -10/05/2014 | D8: 2 | E8: =COUNTIF(F8:ATU8,$E$5) -> 2 | BQ8: X | BR8: X
A9: =MATCH(C9,CV!$C$2:$C$39,0) -> 6 | B9: =VLOOKUP(A9,CV!$A$2:$B$1899,2,FALSE) -> Εγκατάσταση – παραμετροποίηση και παροχή υπηρεσιών υποστήριξης εικονικού περιβάλλοντος λειτουργίας των εφαρμογών του Παρατηρητηρίου. Storage Dell | C9: 01/10/2014 -01/12/2014 | D9: 2 | E9: =COUNTIF(F9:ATU9,$E$5) -> 2 | BX9: X | BY9: X
A10: =MATCH(C10,CV!$C$2:$C$39,0) -> 27 | B10: =VLOOKUP(A10,CV!$A$2:$B$1899,2,FALSE) -> Αναβάθμιση και μετάπτωση της κεντρικής υποδομής της ηλεκτρονικής VISA - Storage | C10: 01/09/2021 - 01/11/2021 | D10: 2 | E10: =COUNTIF(F10:ATU10,$E$5) -> 2 | FC10: X | FD10: X
A11: =MATCH(C11,CV!$C$2:$C$39,0) -> 36 | B11: =VLOOKUP(A11,CV!$A$2:$B$1899,2,FALSE) -> Μετάπτωση εφαρμογών σε νέο storage | C11: 12/2023 – 02/2024 | D11: 2 | E11: =COUNTIF(F11:ATU11,$E$5) -> 2 | GC11: X | GD11: X
A12: =MATCH(C12,CV!$C$2:$C$39,0) -> 8 | B12: =VLOOKUP(A12,CV!$A$2:$B$1899,2,FALSE) -> Εγκατάσταση και παραμετροποίηση και παροχή υπηρεσιών υποστήριξης ΙΤ εξοπλισμού, σε επίπεδο servers και τοπικών υπηρεσιών ανά τις πρεσβείες Storage HP | C12: 01/04/2011 - 01/07/2011 | D12: 3 | E12: =COUNTIF(F12:ATU12,$E$5) -> 3 | AH12: X | AI12: X | AJ12: X
A13: =MATCH(C13,CV!$C$2:$C$39,0) -> 1 | B13: =VLOOKUP(A13,CV!$A$2:$B$1899,2,FALSE) -> Εγκατάσταση, παραμετροποίηση και παροχή υπηρεσιών υποστήριξης Blade IBM Server, με IBM Storage για την πλήρη εικονοποίηση όλων των φυσικών servers του λιμενικού σώματος σε virtual περιβάλλον | C13: 01/06/2013 -31/12/2013 | D13: 6 | E13: =COUNTIF(F13:ATU13,$E$5) -> 6 | BG13: X | BH13: X | BI13: X | BJ13: X | BK13: X | BL13: X
A14: =MATCH(C14,CV!$C$2:$C$39,0) -> 14 | B14: =VLOOKUP(A14,CV!$A$2:$B$1899,2,FALSE) -> Εγκατάσταση/Παραμετροποίηση/Υποστήριξ η συστήματος Big Data Analyzing - Storage | C14: 11/2014 – 05/2015 | D14: 4 | E14: =COUNTIF(F14:ATU14,$E$5) -> 4 | BZ14: X | CA14: X | CB14: X | CC14: X
A15: =MATCH(C15,CV!$C$2:$C$39,0) -> 12 | B15: =VLOOKUP(A15,CV!$A$2:$B$1899,2,FALSE) -> Εγκατάσταση παραμετροποίηση και παροχή υπηρεσιών υποστήριξης Storage Dell | C15: 01/2014 – 12/2014 | D15: 5 | E15: =COUNTIF(F15:ATU15,$E$5) -> 5 | BN15: X | BT15: X | BU15: X | BV15: X | BW15: X
A16: =MATCH(C16,CV!$C$2:$C$39,0) -> 9 | B16: =VLOOKUP(A16,CV!$A$2:$B$1899,2,FALSE) -> Ανάπτυξη και εγκατάσταση λογισμικών και εξοπλισμού τους. Υποστήριξη συνολικού δικτύου ( servers, clients, software). Storage IBM | C16: 01/07/2010 - 01/09/2011 | D16: 9 | E16: =COUNTIF(F16:ATU16,$E$5) -> 9 | X16: X | Y16: X | Z16: X | AA16: X | AB16: X | AC16: X | AE16: X | AK16: X | AL16: X
A17: =MATCH(C17,CV!$C$2:$C$39,0) -> 2 | B17: =VLOOKUP(A17,CV!$A$2:$B$1899,2,FALSE) -> Εγκατάσταση παραμετροποίηση και παροχή υπηρεσιών υποστήριξης όλων των υπηρεσιών της Hellas Gold | C17: 30/04/2013 -30/05/2013 | D17: 1 | E17: =COUNTIF(F17:ATU17,$E$5) -> 1 | BE17: X
A18: =MATCH(C18,CV!$C$2:$C$39,0) -> 3 | B18: =VLOOKUP(A18,CV!$A$2:$B$1899,2,FALSE) -> Εγκατάσταση – παραμετροποίηση και παροχή υπηρεσιών υποστήριξης backup SW και παραμετροποίηση – βελτιστοποίηση mail server υπουργείου | C18: 01/02/2014 -01/03/2014 | D18: 2 | E18: =COUNTIF(F18:ATU18,$E$5) -> 1 | BO18: X
A19: =MATCH(C19,CV!$C$2:$C$39,0) -> 13 | B19: =VLOOKUP(A19,CV!$A$2:$B$1899,2,FALSE) -> Εγκατάσταση παραμετροποίηση και μετάβαση παλαιών λογισμικών Linux RedHat6, σε νέους RedHat Servers | C19: 06/2015 – 07/2015 | D19: 1 | E19: =COUNTIF(F19:ATU19,$E$5) -> 1 | CE19: X
A20: =MATCH(C20,CV!$C$2:$C$39,0) -> 16 | B20: =VLOOKUP(A20,CV!$A$2:$B$1899,2,FALSE) -> Ανάπτυξη κώδικα webservice για την φαρμακευτική εταιρεία LEO | C20: 05/2016- 06/2016 | D20: 1 | E20: =COUNTIF(F20:ATU20,$E$5) -> 1 | CP20: X
A21: =MATCH(C21,CV!$C$2:$C$39,0) -> 18 | B21: =VLOOKUP(A21,CV!$A$2:$B$1899,2,FALSE) -> Αναβάθμιση συστημάτων (Vmware) | C21: 04/2017- 05/2017 | D21: 1 | E21: =COUNTIF(F21:ATU21,$E$5) -> 1 | DA21: X
A22: =MATCH(C22,CV!$C$2:$C$39,0) -> 20 | B22: =VLOOKUP(A22,CV!$A$2:$B$1899,2,FALSE) -> Αναβάθμιση/Υποστήριξη συστημάτων παρακολούθησης δικτύου NMS. | C22: 03/2018 – 04/2018 | D22: 1 | E22: =COUNTIF(F22:ATU22,$E$5) -> 1 | DL22: X
A23: =MATCH(C23,CV!$C$2:$C$39,0) -> 21 | B23: =VLOOKUP(A23,CV!$A$2:$B$1899,2,FALSE) -> Εγκατάσταση/Παραμετροποίηση/Υποστήριξ η Cloud υπηρεσιών στην εταιρεία WebIQ | C23: 11/2017 – 12/2017 | D23: 1 | E23: =COUNTIF(F23:ATU23,$E$5) -> 1 | DH23: X
A24: =MATCH(C24,CV!$C$2:$C$39,0) -> 25 | B24: =VLOOKUP(A24,CV!$A$2:$B$1899,2,FALSE) -> Αναβάθμιση συστήματος NMS | C24: 04/2019 – 05/2019 | D24: 1 | E24: =COUNTIF(F24:ATU24,$E$5) -> 1 | DY24: X
A25: =MATCH(C25,CV!$C$2:$C$39,0) -> 29 | B25: =VLOOKUP(A25,CV!$A$2:$B$1899,2,FALSE) -> Εγκατάσταση – Παραμετροποίηση κεντρικής υποδομής ENTRY-EXIT για την ΕΛ.ΑΣ | C25: 01/11/2021 – 01/12/2021 | D25: 1 | E25: =COUNTIF(F25:ATU25,$E$5) -> 1 | FE25: X
A26: =MATCH(C26,CV!$C$2:$C$39,0) -> 33 | B26: =VLOOKUP(A26,CV!$A$2:$B$1899,2,FALSE) -> Αναβάθμιση συστημάτων ΥΠ.ΕΞ | C26: 03/2022 – 04/2022 | D26: 1 | E26: =COUNTIF(F26:ATU26,$E$5) -> 1 | FH26: X
A27: =MATCH(C27,CV!$C$2:$C$39,0) -> 34 | B27: =VLOOKUP(A27,CV!$A$2:$B$1899,2,FALSE) -> Εγκατάσταση – παραμετροποίηση και παροχή υπηρεσιών υποστήριξης Vmware VDI υποδομής στο ΕΑΠ | C27: 06/2022 – 07/2022 | D27: 1 | E27: =COUNTIF(F27:ATU27,$E$5) -> 1 | FK27: X
A28: =MATCH(C28,CV!$C$2:$C$39,0) -> 35 | B28: =VLOOKUP(A28,CV!$A$2:$B$1899,2,FALSE) -> Αναβάθμιση virtualized συστημάτων στην Εθνική Επιτροπή Ατομικών Ερευνών | C28: 08/2023 – 09/2023 | D28: 1 | E28: =COUNTIF(F28:ATU28,$E$5) -> 1 | FY28: X
A29: =MATCH(C29,CV!$C$2:$C$39,0) -> 38 | B29: =VLOOKUP(A29,CV!$A$2:$B$1899,2,FALSE) -> Συγγραφή Μελέτης Εφαρμογής | C29: 06/2024 – 07/2024 | D29: 1 | E29: =COUNTIF(F29:ATU29,$E$5) -> 1 | GI29: X
A30: =MATCH(C30,CV!$C$2:$C$39,0) -> 23 | B30: =VLOOKUP(A30,CV!$A$2:$B$1899,2,FALSE) -> Εγκατάσταση/Υποστήριξη messaging system πολιτικής αεροπορίας. | C30: 04/2018 – 06/2018 | D30: 2 | E30: =COUNTIF(F30:ATU30,$E$5) -> 2 | DM30: X | DN30: X
A31: =MATCH(C31,CV!$C$2:$C$39,0) -> 31 | B31: =VLOOKUP(A31,CV!$A$2:$B$1899,2,FALSE) -> Σχεδιασμός μετάπτωσης υπηρεσίας Azure cloud Mail πολυτεχνείου Κρήτης | C31: 10/09/2021 – 11/2021 | D31: 1 | E31: =COUNTIF(F31:ATU31,$E$5) -> 1 | FB31: X
A32: =MATCH(C32,CV!$C$2:$C$39,0) -> 7 | B32: =VLOOKUP(A32,CV!$A$2:$B$1899,2,FALSE) -> Εγκατάσταση και παραμετροποίηση και παροχή υπηρεσιών υποστήριξης των λειτουργικών συστημάτων, εγκατάσταση και παραμετροποίηση των servers του συστήματος. Υποστήριξη 2ου επιπέδου | C32: 01/01/2011 - 01/04/2011 | D32: 3 | E32: =COUNTIF(F32:ATU32,$E$5) -> 3 | AD32: X | AF32: X | AG32: X
A33: =MATCH(C33,CV!$C$2:$C$39,0) -> 15 | B33: =VLOOKUP(A33,CV!$A$2:$B$1899,2,FALSE) -> Σχεδιασμός λύσης, Υλοποίηση, Παραμετροποίηση και συντήρηση- υποστήριξη σύμφωνα με τις ανάγκες της εταιρείας | C33: 04/2016 – 07/2016 | D33: 1 | E33: =COUNTIF(F33:ATU33,$E$5) -> 1 | CO33: X
A34: =MATCH(C34,CV!$C$2:$C$39,0) -> 19 | B34: =VLOOKUP(A34,CV!$A$2:$B$1899,2,FALSE) -> Σχεδιασμός, εγκατάσταση, παραμετροποίηση και υποστήριξη υπηρεσίας Video/Game Streaming στο δίκτυο του ΟΠΑΠ | C34: 04/2018 – 07/2018 | D34: 3 | E34: =COUNTIF(F34:ATU34,$E$5) -> 2 | DO34: X | DP34: X
A35: =MATCH(C35,CV!$C$2:$C$39,0) -> 28 | B35: =VLOOKUP(A35,CV!$A$2:$B$1899,2,FALSE) -> Σχεδίαση/Αναβάθμιση/Υποστήριξη/Μετάπτ ωση Webmail ΕΛ.ΑΣ | C35: 29/03/2021 – 07/2021 | D35: 3 | E35: =COUNTIF(F35:ATU35,$E$5) -> 3 | EV35: X | EW35: X | EX35: X
A36: =MATCH(C36,CV!$C$2:$C$39,0) -> 26 | B36: =VLOOKUP(A36,CV!$A$2:$B$1899,2,FALSE) -> Αναβάθμιση συστημάτων (Vmware) όλου του ομίλου | C36: 09/2019 – 02/2020 | D36: 5 | E36: =COUNTIF(F36:ATU36,$E$5) -> 5 | ED36: X | EE36: X | EF36: X | EG36: X | EH36: X
A37: =MATCH(C37,CV!$C$2:$C$39,0) -> 32 | B37: =VLOOKUP(A37,CV!$A$2:$B$1899,2,FALSE) -> Εγκατάσταση και παραμετροποίηση Vmware φάρμας για την υποστήριξη των μηχανημάτων του έργου | C37: 05/2022 – 11/2022 | D37: 6 | E37: =COUNTIF(F37:ATU37,$E$5) -> 6 | FJ37: X | FL37: X | FM37: X | FN37: X | FO37: X | FP37: X
A38: =MATCH(C38,CV!$C$2:$C$39,0) -> 10 | B38: =VLOOKUP(A38,CV!$A$2:$B$1899,2,FALSE) -> Εγκατάσταση/παραμετροποίηση των ραντάρ, εγκατάσταση παραμετροποίηση των λογισμικών, υποστήριξη και επίλυση δυσλειτουργιών σε επίπεδο ραντάρ και λογισμικό αυτών σε επίπεδο 1ο , 2ο και 3ο . | C38: 07/07/2011 - 21/04/2012 | D38: 5 | E38: =COUNTIF(F38:ATU38,$E$5) -> 5 | AN38: X | AO38: X | AP38: X | AQ38: X | AR38: X
A39: =MATCH(C39,CV!$C$2:$C$39,0) -> 22 | B39: =VLOOKUP(A39,CV!$A$2:$B$1899,2,FALSE) -> Αναβάθμιση συστημάτων παρακολούθησης δικτύου NMS. | C39: 01/2018 – 10/2018 | D39: 9 | E39: =COUNTIF(F39:ATU39,$E$5) -> 5 | DJ39: X | DK39: X | DQ39: X | DR39: X | DS39: X
A40: =MATCH(C40,CV!$C$2:$C$39,0) -> 24 | B40: =VLOOKUP(A40,CV!$A$2:$B$1899,2,FALSE) -> Υποστήριξη Cloud υπηρεσιών MITA | C40: 06/2019 – 10/2020 | D40: 16 | E40: =COUNTIF(F40:ATU40,$E$5) -> 12 | EA40: X | EB40: X | EC40: X | EI40: X | EJ40: X | EK40: X | EL40: X | EM40: X | EN40: X | EO40: X | EP40: X | EQ40: X
A41: =MATCH(C41,CV!$C$2:$C$39,0) -> 17 | B41: =VLOOKUP(A41,CV!$A$2:$B$1899,2,FALSE) -> Σχεδιασμός, εγκατάσταση και παραμετροποίηση δικτύου ραντάρ υποστήριξης Αεροδρομίων Λάρνακας και Πάφου και παροχή υπηρεσιών υποστήριξης | C41: 02/2017 – 07/2018 | D41: 17 | E41: =COUNTIF(F41:ATU41,$E$5) -> 9 | CY41: X | CZ41: X | DB41: X | DC41: X | DD41: X | DE41: X | DF41: X | DG41: X | DI41: X
A42: =MATCH(C42,CV!$C$2:$C$39,0) -> 11 | B42: =VLOOKUP(A42,CV!$A$2:$B$1899,2,FALSE) -> Εγκατάσταση/παραμετροποίηση των ραντάρ, εγκατάσταση παραμετροποίηση των λογισμικών, υποστήριξη και επίλυση δυσλειτουργιών σε επίπεδο ραντάρ και λογισμικό αυτών σε επίπεδο 1ο , 2ο και 3ο . | C42: 01/03/2009 - 01/11/2010 | D42: 10 | E42: =COUNTIF(F42:ATU42,$E$5) -> 10 | H42: X | I42: X | J42: X | K42: X | L42: X | M42: X | N42: X | O42: X | P42: X | Q42: X
...
